Workbook

Sheet Dashboard
A1: Sony Group Corporation — Stock Analytics Dashboard
A3: Dataset | B3: Sony stock data (2014–2026)
A4: Trading days | B4: =Calculations!B2
A5: Latest close | B5: =Calculations!B4
A6: Historical high | B6: =Calculations!B5
A7: Historical low | B7: =Calculations!B6
A8: Average close | B8: =Calculations!B7
A9: Avg daily volume | B9: =Calculations!B8
A10: Daily return volatility | B10: =Calculations!B10
A12: Note: Historical analysis is educational and does not constitute investment advice.

Sheet Raw_Data
A1: Date | B1: Close | C1: High | D1: Low | E1: Open | F1: Volume
A2: 41641 | B2: 3.2039406 | C2: 3.2468839 | D2: 3.1890038 | E2: 3.2356814 | F2: 13127000
A3: 41642 | B3: 3.2076747 | C3: 3.2226113 | D3: 3.1964721 | E3: 3.2132759 | F3: 4642000
A4: 41645 | B4: 3.2300792 | C4: 3.2655539 | D4: 3.2244778 | E4: 3.2300792 | F4: 11781500
A5: 41646 | B5: 3.2338145 | C5: 3.2450171 | D5: 3.2114094 | E5: 3.2412828 | F5: 17191500
A6: 41647 | B6: 3.4074538 | C6: 3.4205234 | D6: 3.2226109 | E6: 3.2487504 | F6: 42864500
A7: 41648 | B7: 3.3757133 | C7: 3.3962515 | D7: 3.3570424 | E7: 3.3906502 | F7: 13011000
A8: 41649 | B8: 3.3234348 | C8: 3.3290362 | D8: 3.2618206 | E8: 3.3103652 | F8: 17033500
A9: 41652 | B9: 3.2767572 | C9: 3.3178333 | D9: 3.2692889 | E9: 3.3010295 | F9: 24355000
A10: 41653 | B10: 3.2730229 | C10: 3.2860925 | D10: 3.2394151 | E10: 3.2562189 | F10: 14303500
A11: 41654 | B11: 3.250618 | C11: 3.2692889 | D11: 3.2375481 | E11: 3.2468836 | F11: 13571000
A12: 41655 | B12: 3.2132761 | C12: 3.2338143 | D12: 3.2058079 | E12: 3.226346 | F12: 11705000
A13: 41656 | B13: 3.1834025 | C13: 3.2207445 | D13: 3.1834025 | E13: 3.2039405 | F13: 9680500
... A3180: 46258 | B3180: 24.26 | C3180: 24.32 | D3180: 24.1 | E3180: 24.15 | F3180: 3191700

Sheet Clean_Data
A1: Date | B1: Open | C1: High | D1: Low | E1: Close | F1: Volume | G1: Previous_Close | H1: Daily_Price_Change | I1: Daily_Return_% | J1: Intraday_Range | K1: Intraday_Range_% | L1: SMA_7 | M1: SMA_30 | N1: SMA_50 | O1: SMA_200 | P1: Rolling_30D_Volatility_% | Q1: Year | R1: Month | S1: Month_Name | T1: Quarter | U1: Day_of_Week
A2: 41641 | B2: 3.2356814 | C2: 3.2468839 | D2: 3.1890038 | E2: 3.2039406 | F2: 13127000 | J2: 0.057880081 | K2: 1.7888065 | Q2: 2014 | R2: 1 | S2: January | T2: Q1 | U2: Thursday
A3: 41642 | B3: 3.2132759 | C3: 3.2226113 | D3: 3.1964721 | E3: 3.2076747 | F3: 4642000 | G3: 3.2039406 | H3: 0.0037341118 | I3: 0.11654747 | J3: 0.02613926 | K3: 0.81347701 | Q3: 2014 | R3: 1 | S3: January | T3: Q1 | U3: Friday
A4: 41645 | B4: 3.2300792 | C4: 3.2655539 | D4: 3.2244778 | E4: 3.2300792 | F4: 11781500 | G4: 3.2076747 | H4: 0.022404432 | I4: 0.69846334 | J4: 0.041076067 | K4: 1.2716737 | Q4: 2014 | R4: 1 | S4: January | T4: Q1 | U4: Monday
A5: 41646 | B5: 3.2412828 | C5: 3.2450171 | D5: 3.2114094 | E5: 3.2338145 | F5: 17191500 | G5: 3.2300792 | H5: 0.0037353039 | I5: 0.11564125 | J5: 0.033607784 | K5: 1.0368668 | Q5: 2014 | R5: 1 | S5: January | T5: Q1 | U5: Tuesday
A6: 41647 | B6: 3.2487504 | C6: 3.4205234 | D6: 3.2226109 | E6: 3.4074538 | F6: 42864500 | G6: 3.2338145 | H6: 0.1736393 | I6: 5.3694885 | J6: 0.1979125 | K6: 6.0919578 | Q6: 2014 | R6: 1 | S6: January | T6: Q1 | U6: Wednesday
A7: 41648 | B7: 3.3906502 | C7: 3.3962515 | D7: 3.3570424 | E7: 3.3757133 | F7: 13011000 | G7: 3.4074538 | H7: -0.031740427 | I7: -0.93149986 | J7: 0.039209112 | K7: 1.1563892 | Q7: 2014 | R7: 1 | S7: January | T7: Q1 | U7: Thursday
A8: 41649 | B8: 3.3103652 | C8: 3.3290362 | D8: 3.2618206 | E8: 3.3234348 | F8: 17033500 | G8: 3.3757133 | H8: -0.052278519 | I8: -1.5486658 | J8: 0.067215562 | K8: 2.0304576 | L8: 3.2831587 | Q8: 2014 | R8: 1 | S8: January | T8: Q1 | U8: Friday
A9: 41652 | B9: 3.3010295 | C9: 3.3178333 | D9: 3.2692889 | E9: 3.2767572 | F9: 24355000 | G9: 3.3234348 | H9: -0.046677589 | I9: -1.4044984 | J9: 0.048544372 | K9: 1.4705828 | L9: 3.2935611 | Q9: 2014 | R9: 1 | S9: January | T9: Q1 | U9: Monday
A10: 41653 | B10: 3.2562189 | C10: 3.2860925 | D10: 3.2394151 | E10: 3.2730229 | F10: 14303500 | G10: 3.2767572 | H10: -0.0037343502 | I10: -0.11396481 | J10: 0.046677406 | K10: 1.4334849 | L10: 3.3028965 | Q10: 2014 | R10: 1 | S10: January | T10: Q1 | U10: Tuesday
A11: 41654 | B11: 3.2468836 | C11: 3.2692889 | D11: 3.2375481 | E11: 3.250618 | F11: 13571000 | G11: 3.2730229 | H11: -0.022404909 | I11: -0.68453261 | J11: 0.031740816 | K11: 0.97757789 | L11: 3.3058306 | Q11: 2014 | R11: 1 | S11: January | T11: Q1 | U11: Wednesday
A12: 41655 | B12: 3.226346 | C12: 3.2338143 | D12: 3.2058079 | E12: 3.2132761 | F12: 11705000 | G12: 3.250618 | H12: -0.037341833 | I12: -1.148761 | J12: 0.028006448 | K12: 0.86805471 | L12: 3.3028966 | Q12: 2014 | R12: 1 | S12: January | T12: Q1 | U12: Thursday
A13: 41656 | B13: 3.2039405 | C13: 3.2207445 | D13: 3.1834025 | E13: 3.1834025 | F13: 9680500 | G13: 3.2132761 | H13: -0.02987361 | I13: -0.92969319 | J13: 0.037341929 | K13: 1.1655001 | L13: 3.2708893 | Q13: 2014 | R13: 1 | S13: January | T13: Q1 | U13: Friday
A14: 41660 | B14: 3.1834029 | C14: 3.1852698 | D14: 3.1404596 | E14: 3.1460607 | F14: 14266500 | G14: 3.1834025 | H14: -0.037341833 | I14: -1.1730164 | J14: 0.04481023 | K14: 1.4076205 | L14: 3.2380818 | Q14: 2014 | R14: 1 | S14: January | T14: Q1 | U14: Tuesday
A15: 41661 | B15: 3.1497949 | C15: 3.1983395 | D15: 3.1460605 | E15: 3.1946051 | F15: 19626500 | G15: 3.1460607 | H15: 0.048544407 | I15: 1.5430219 | J15: 0.052278969 | K15: 1.6597579 | L15: 3.2196775 | Q15: 2014 | R15: 1 | S15: January | T15: Q1 | U15: Wednesday
A16: 41662 | B16: 3.1647315 | C16: 3.1703326 | D16: 3.1124528 | E16: 3.1348579 | F16: 11469000 | G16: 3.1946051 | H16: -0.059747219 | I16: -1.8702537 | J16: 0.057879855 | K16: 1.8289025 | L16: 3.1994062 | Q16: 2014 | R16: 1 | S16: January | T16: Q1 | U16: Thursday
A17: 41663 | B17: 3.1497952 | C17: 3.1572635 | D17: 3.1049847 | E17: 3.1217887 | F17: 15650000 | G17: 3.1348579 | H17: -0.013069153 | I17: -0.41689778 | J17: 0.052278752 | K17: 1.6597508 | L17: 3.1778013 | Q17: 2014 | R17: 1 | S17: January | T17: Q1 | U17: Friday
A18: 41666 | B18: 3.0751116 | C18: 3.0863142 | D18: 2.9425476 | E18: 3.0303013 | F18: 33966500 | G18: 3.1217887 | H18: -0.091487408 | I18: -2.9306085 | J18: 0.14376665 | K18: 4.6751684 | L18: 3.1463275 | Q18: 2014 | R18: 1 | S18: January | T18: Q1 | U18: Monday
A19: 41667 | B19: 2.9985598 | C19: 3.0751109 | D19: 2.9929587 | E19: 3.0657754 | F19: 10703000 | G19: 3.0303013 | H19: 0.035474062 | I19: 1.1706447 | J19: 0.082152159 | K19: 2.7397205 | L19: 3.125256 | Q19: 2014 | R19: 1 | S19: January | T19: Q1 | U19: Tuesday
... A30: 41682 | B30: 3.1964725 | C30: 3.2412828 | D30: 3.1946054 | E30: 3.2338145 | F30: 13905500 | G30: 3.1946051 | H30: 0.039209366 | I30: 1.2273619 | J30: 0.046677416 | K30: 1.460279 | L30: 3.1060514 | Q30: 2014 | R30: 2 | S30: February | T30: Q1 | U30: Wednesday
A31: 41683 | B31: 3.1441931 | C31: 3.2263454 | D31: 3.1273891 | E31: 3.2114086 | F31: 21296500 | G31: 3.2338145 | H31: -0.022405863 | I31: -0.69286173 | J31: 0.098956367 | K31: 3.1472739 | L31: 3.1353915 | M31: 3.1540891 | Q31: 2014 | R31: 2 | S31: February | T31: Q1 | U31: Thursday
A32: 41684 | B32: 3.1348578 | C32: 3.1983392 | D32: 3.1348578 | E32: 3.1852694 | F32: 20059500 | G32: 3.2114086 | H32: -0.026139259 | I32: -0.81394997 | J32: 0.063481409 | K32: 2.0250172 | L32: 3.1663319 | M32: 3.1534667 | P32: 2.1710671 | Q32: 2014 | R32: 2 | S32: February | T32: Q1 | U32: Friday
A33: 41688 | B33: 3.2300803 | C33: 3.2468841 | D33: 3.2114093 | E33: 3.2375486 | F33: 9163500 | G33: 3.1852694 | H33: 0.052279234 | I33: 1.6412814 | J33: 0.035474747 | K33: 1.0982621 | L33: 3.1882037 | M33: 3.1544625 | P33: 2.1915678 | Q33: 2014 | R33: 2 | S33: February | T33: Q1 | U33: Tuesday
A34: 41689 | B34: 3.1946049 | C34: 3.2207444 | D34: 3.1778012 | E34: 3.1871367 | F34: 13277000 | G34: 3.2375486 | H34: -0.05041194 | I34: -1.5571022 | J34: 0.042943262 | K34: 1.3442433 | L34: 3.1948719 | M34: 3.1530311 | P34: 2.2073225 | Q34: 2014 | R34: 2 | S34: February | T34: Q1 | U34: Wednesday
A35: 41690 | B35: 3.1927376 | C35: 3.2151427 | D35: 3.1703322 | E35: 3.2058072 | F35: 8962000 | G35: 3.1871367 | H35: 0.018670559 | I35: 0.5858098 | J35: 0.044810442 | K35: 1.4035116 | L35: 3.2079414 | M35: 3.1520975 | P35: 2.2099966 | Q35: 2014 | R35: 2 | S35: February | T35: Q1 | U35: Thursday
A36: 41691 | B36: 3.2188775 | C36: 3.2356815 | D36: 3.1964724 | E36: 3.1964724 | F36: 7017500 | G36: 3.2058072 | H36: -0.0093348026 | I36: -0.29118415 | J36: 0.039209117 | K36: 1.2180991 | L36: 3.2082082 | M36: 3.1450648 | P36: 1.9630991 | Q36: 2014 | R36: 2 | S36: February | T36: Q1 | U36: Friday
A37: 41694 | B37: 3.2487509 | C37: 3.2636877 | D37: 3.2338141 | E37: 3.2487509 | F37: 9817000 | G37: 3.1964724 | H37: 0.052278519 | I37: 1.6355066 | J37: 0.029873632 | K37: 0.91954209 | L37: 3.210342 | M37: 3.1408327 | P37: 1.9856782 | Q37: 2014 | R37: 2 | S37: February | T37: Q1 | U37: Monday
A38: 41695 | B38: 3.2226116 | C38: 3.2394156 | D38: 3.2058079 | E38: 3.226346 | F38: 9754000 | G38: 3.2487509 | H38: -0.022404909 | I38: -0.68964687 | J38: 0.033607783 | K38: 1.0428741 | L38: 3.2124759 | M38: 3.1375964 | P38: 1.9703339 | Q38: 2014 | R38: 2 | S38: February | T38: Q1 | U38: Tuesday
A39: 41696 | B39: 3.239416 | C39: 3.2730237 | D39: 3.203941 | E39: 3.2450173 | F39: 8785000 | G39: 3.226346 | H39: 0.018671274 | I39: 0.5787127 | J39: 0.069082757 | K39: 2.1325683 | L39: 3.2210113 | M39: 3.1365384 | P39: 1.9575987 | Q39: 2014 | R39: 2 | S39: February | T39: Q1 | U39: Wednesday
A40: 41697 | B40: 3.245017 | C40: 3.2935616 | D40: 3.2244789 | E40: 3.2711563 | F40: 15480500 | G40: 3.2450173 | H40: 0.026139021 | I40: 0.80551253 | J40: 0.069082752 | K40: 2.1288872 | L40: 3.2258124 | M40: 3.1364762 | P40: 1.9631712 | Q40: 2014 | R40: 2 | S40: February | T40: Q1 | U40: Thursday
A41: 41698 | B41: 3.2730231 | C41: 3.2972954 | D41: 3.2543521 | E41: 3.2767572 | F41: 11012000 | G41: 3.2711563 | H41: 0.0056009293 | I41: 0.17122169 | J41: 0.042943261 | K41: 1.3120366 | L41: 3.2386153 | M41: 3.1373475 | P41: 1.9588455 | Q41: 2014 | R41: 2 | S41: February | T41: Q1 | U41: Friday
A42: 41701 | B42: 3.2114092 | C42: 3.226346 | D42: 3.1815356 | E42: 3.2132761 | F42: 9114000 | G42: 3.2767572 | H42: -0.063481092 | I42: -1.9373145 | J42: 0.044810451 | K42: 1.3953516 | L42: 3.2396823 | M42: 3.1373475 | P42: 1.9805876 | Q42: 2014 | R42: 3 | S42: March | T42: Q1 | U42: Monday
A43: 41702 | B43: 3.2543521 | C43: 3.2711559 | D43: 3.2319467 | E43: 3.2412822 | F43: 7286000 | G43: 3.2132761 | H43: 0.028006077 | I43: 0.87157392 | J43: 0.039209112 | K43: 1.2048208 | L43: 3.2460837 | M43: 3.1392768 | P43: 1.9781441 | Q43: 2014 | R43: 3 | S43: March | T43: Q1 | U43: Tuesday
... A50: 41711 | B50: 3.3383711 | C50: 3.3402383 | D50: 3.2674214 | E50: 3.2916937 | F50: 12166000 | G50: 3.3309035 | H50: -0.039209843 | I50: -1.1771534 | J50: 0.072816884 | K50: 2.18121 | L50: 3.3247685 | M50: 3.1920534 | P50: 1.820892 | Q50: 2014 | R50: 3 | S50: March | T50: Q1 | U50: Thursday
A51: 41712 | B51: 3.222611 | C51: 3.2356808 | D51: 3.1964717 | E51: 3.2058072 | F51: 15427500 | G51: 3.2916937 | H51: -0.085886478 | I51: -2.6091881 | J51: 0.039209109 | K51: 1.2166876 | L51: 3.3164999 | M51: 3.198526 | N51: 3.1967336 | P51: 1.8977125 | Q51: 2014 | R51: 3 | S51: March | T51: Q1 | U51: Friday
A52: 41715 | B52: 3.2020736 | C52: 3.2375483 | D52: 3.2020736 | E52: 3.2151432 | F52: 6010500 | G52: 3.2058072 | H52: 0.0093359947 | I52: 0.29122134 | J52: 0.035474744 | K52: 1.1078679 | L52: 3.2994293 | M52: 3.2076748 | N52: 3.1969576 | P52: 1.8340108 | Q52: 2014 | R52: 3 | S52: March | T52: Q1 | U52: Monday
A53: 41716 | B53: 3.1703332 | C53: 3.2132765 | D53: 3.1591308 | E53: 3.2020741 | F53: 9698000 | G53: 3.2151432 | H53: -0.013069153 | I53: -0.40648743 | J53: 0.054145717 | K53: 1.7078872 | L53: 3.2780911 | M53: 3.2194998 | N53: 3.1968456 | P53: 1.7184359 | Q53: 2014 | R53: 3 | S53: March | T53: Q1 | U53: Tuesday
A54: 41717 | B54: 3.2058082 | C54: 3.239416 | D54: 3.1815359 | E54: 3.2020741 | F54: 17635500 | G54: 3.2020741 | H54: 0 | I54: 0 | J54: 0.057880088 | K54: 1.8054757 | L54: 3.2543523 | M54: 3.2260346 | N54: 3.1962855 | P54: 1.4149875 | Q54: 2014 | R54: 3 | S54: March | T54: Q1 | U54: Wednesday
A55: 41718 | B55: 3.2338144 | C55: 3.2898273 | D55: 3.2319472 | E55: 3.2879603 | F55: 15960000 | G55: 3.2020741 | H55: 0.08588624 | I55: 2.6822066 | J55: 0.057880083 | K55: 1.7898394 | L55: 3.2479509 | M55: 3.2366771 | N55: 3.1973684 | P55: 1.4559153 | Q55: 2014 | R55: 3 | S55: March | T55: Q1 | U55: Thursday
A56: 41719 | B56: 3.2879594 | C56: 3.3327697 | D56: 3.2879594 | E56: 3.3159659 | F56: 20048500 | G56: 3.2879603 | H56: 0.0280056 | I56: 0.85176211 | J56: 0.044810218 | K56: 1.362858 | L56: 3.2458169 | M56: 3.2443944 | N56: 3.1955387 | P56: 1.2975155 | Q56: 2014 | R56: 3 | S56: March | T56: Q1 | U56: Friday
...

Sheet Calculations
A1: Metric | B1: Value | C1: Interpretation
A2: Trading days | B2: =COUNTA(Clean_Data!A2:A3180) | C2: Number of observations
A3: First closing price | B3: =Clean_Data!E2 | C3: First recorded close
A4: Latest closing price | B4: =LOOKUP(2,1/(Clean_Data!E:E<>""),Clean_Data!E:E) | C4: Latest recorded close
A5: Historical high | B5: =MAX(Clean_Data!E:E) | C5: Maximum closing price
A6: Historical low | B6: =MIN(Clean_Data!E:E) | C6: Minimum closing price
A7: Average closing price | B7: =AVERAGE(Clean_Data!E:E) | C7: Mean closing price
A8: Average daily volume | B8: =AVERAGE(Clean_Data!F:F) | C8: Mean shares traded
A9: Average daily return | B9: =AVERAGE(Clean_Data!I:I) | C9: Mean daily return (%)
A10: Daily return volatility | B10: =STDEV.S(Clean_Data!I:I) | C10: Standard deviation of daily returns (%)
A11: Total price change | B11: =C4/C3-1 | C11: Price change from first to latest close

Sheet Yearly_Analysis
A1: Year | B1: Average Close | C1: First Close | D1: Last Close | E1: Annual Return % | F1: Max Close | G1: Min Close | H1: Average Volume | I1: Volatility %
A2: 2014 | B2: =AVERAGEIF(Clean_Data!$Q:$Q,A2,Clean_Data!$E:$E) | C2: =INDEX(Clean_Data!$E:$E,MATCH(A2,Clean_Data!$Q:$Q,0)) | D2: =LOOKUP(2,1/(Clean_Data!$Q:$Q=A2),Clean_Data!$E:$E) | E2: =D2/C2-1 | F2: =MAXIFS(Clean_Data!$E:$E,Clean_Data!$Q:$Q,A2) | G2: =MINIFS(Clean_Data!$E:$E,Clean_Data!$Q:$Q,A2) | H2: =AVERAGEIF(Clean_Data!$Q:$Q,A2,Clean_Data!$F:$F)
A3: 2015 | B3: =AVERAGEIF(Clean_Data!$Q:$Q,A3,Clean_Data!$E:$E) | C3: =INDEX(Clean_Data!$E:$E,MATCH(A3,Clean_Data!$Q:$Q,0)) | D3: =LOOKUP(2,1/(Clean_Data!$Q:$Q=A3),Clean_Data!$E:$E) | E3: =D3/C3-1 | F3: =MAXIFS(Clean_Data!$E:$E,Clean_Data!$Q:$Q,A3) | G3: =MINIFS(Clean_Data!$E:$E,Clean_Data!$Q:$Q,A3) | H3: =AVERAGEIF(Clean_Data!$Q:$Q,A3,Clean_Data!$F:$F)
A4: 2016 | B4: =AVERAGEIF(Clean_Data!$Q:$Q,A4,Clean_Data!$E:$E) | C4: =INDEX(Clean_Data!$E:$E,MATCH(A4,Clean_Data!$Q:$Q,0)) | D4: =LOOKUP(2,1/(Clean_Data!$Q:$Q=A4),Clean_Data!$E:$E) | E4: =D4/C4-1 | F4: =MAXIFS(Clean_Data!$E:$E,Clean_Data!$Q:$Q,A4) | G4: =MINIFS(Clean_Data!$E:$E,Clean_Data!$Q:$Q,A4) | H4: =AVERAGEIF(Clean_Data!$Q:$Q,A4,Clean_Data!$F:$F)
A5: 2017 | B5: =AVERAGEIF(Clean_Data!$Q:$Q,A5,Clean_Data!$E:$E) | C5: =INDEX(Clean_Data!$E:$E,MATCH(A5,Clean_Data!$Q:$Q,0)) | D5: =LOOKUP(2,1/(Clean_Data!$Q:$Q=A5),Clean_Data!$E:$E) | E5: =D5/C5-1 | F5: =MAXIFS(Clean_Data!$E:$E,Clean_Data!$Q:$Q,A5) | G5: =MINIFS(Clean_Data!$E:$E,Clean_Data!$Q:$Q,A5) | H5: =AVERAGEIF(Clean_Data!$Q:$Q,A5,Clean_Data!$F:$F)
A6: 2018 | B6: =AVERAGEIF(Clean_Data!$Q:$Q,A6,Clean_Data!$E:$E) | C6: =INDEX(Clean_Data!$E:$E,MATCH(A6,Clean_Data!$Q:$Q,0)) | D6: =LOOKUP(2,1/(Clean_Data!$Q:$Q=A6),Clean_Data!$E:$E) | E6: =D6/C6-1 | F6: =MAXIFS(Clean_Data!$E:$E,Clean_Data!$Q:$Q,A6) | G6: =MINIFS(Clean_Data!$E:$E,Clean_Data!$Q:$Q,A6) | H6: =AVERAGEIF(Clean_Data!$Q:$Q,A6,Clean_Data!$F:$F)
A7: 2019 | B7: =AVERAGEIF(Clean_Data!$Q:$Q,A7,Clean_Data!$E:$E) | C7: =INDEX(Clean_Data!$E:$E,MATCH(A7,Clean_Data!$Q:$Q,0)) | D7: =LOOKUP(2,1/(Clean_Data!$Q:$Q=A7),Clean_Data!$E:$E) | E7: =D7/C7-1 | F7: =MAXIFS(Clean_Data!$E:$E,Clean_Data!$Q:$Q,A7) | G7: =MINIFS(Clean_Data!$E:$E,Clean_Data!$Q:$Q,A7) | H7: =AVERAGEIF(Clean_Data!$Q:$Q,A7,Clean_Data!$F:$F)
A8: 2020 | B8: =AVERAGEIF(Clean_Data!$Q:$Q,A8,Clean_Data!$E:$E) | C8: =INDEX(Clean_Data!$E:$E,MATCH(A8,Clean_Data!$Q:$Q,0)) | D8: =LOOKUP(2,1/(Clean_Data!$Q:$Q=A8),Clean_Data!$E:$E) | E8: =D8/C8-1 | F8: =MAXIFS(Clean_Data!$E:$E,Clean_Data!$Q:$Q,A8) | G8: =MINIFS(Clean_Data!$E:$E,Clean_Data!$Q:$Q,A8) | H8: =AVERAGEIF(Clean_Data!$Q:$Q,A8,Clean_Data!$F:$F)
A9: 2021 | B9: =AVERAGEIF(Clean_Data!$Q:$Q,A9,Clean_Data!$E:$E) | C9: =INDEX(Clean_Data!$E:$E,MATCH(A9,Clean_Data!$Q:$Q,0)) | D9: =LOOKUP(2,1/(Clean_Data!$Q:$Q=A9),Clean_Data!$E:$E) | E9: =D9/C9-1 | F9: =MAXIFS(Clean_Data!$E:$E,Clean_Data!$Q:$Q,A9) | G9: =MINIFS(Clean_Data!$E:$E,Clean_Data!$Q:$Q,A9) | H9: =AVERAGEIF(Clean_Data!$Q:$Q,A9,Clean_Data!$F:$F)
A10: 2022 | B10: =AVERAGEIF(Clean_Data!$Q:$Q,A10,Clean_Data!$E:$E) | C10: =INDEX(Clean_Data!$E:$E,MATCH(A10,Clean_Data!$Q:$Q,0)) | D10: =LOOKUP(2,1/(Clean_Data!$Q:$Q=A10),Clean_Data!$E:$E) | E10: =D10/C10-1 | F10: =MAXIFS(Clean_Data!$E:$E,Clean_Data!$Q:$Q,A10) | G10: =MINIFS(Clean_Data!$E:$E,Clean_Data!$Q:$Q,A10) | H10: =AVERAGEIF(Clean_Data!$Q:$Q,A10,Clean_Data!$F:$F)
A11: 2023 | B11: =AVERAGEIF(Clean_Data!$Q:$Q,A11,Clean_Data!$E:$E) | C11: =INDEX(Clean_Data!$E:$E,MATCH(A11,Clean_Data!$Q:$Q,0)) | D11: =LOOKUP(2,1/(Clean_Data!$Q:$Q=A11),Clean_Data!$E:$E) | E11: =D11/C11-1 | F11: =MAXIFS(Clean_Data!$E:$E,Clean_Data!$Q:$Q,A11) | G11: =MINIFS(Clean_Data!$E:$E,Clean_Data!$Q:$Q,A11) | H11: =AVERAGEIF(Clean_Data!$Q:$Q,A11,Clean_Data!$F:$F)
A12: 2024 | B12: =AVERAGEIF(Clean_Data!$Q:$Q,A12,Clean_Data!$E:$E) | C12: =INDEX(Clean_Data!$E:$E,MATCH(A12,Clean_Data!$Q:$Q,0)) | D12: =LOOKUP(2,1/(Clean_Data!$Q:$Q=A12),Clean_Data!$E:$E) | E12: =D12/C12-1 | F12: =MAXIFS(Clean_Data!$E:$E,Clean_Data!$Q:$Q,A12) | G12: =MINIFS(Clean_Data!$E:$E,Clean_Data!$Q:$Q,A12) | H12: =AVERAGEIF(Clean_Data!$Q:$Q,A12,Clean_Data!$F:$F)
A13: 2025 | B13: =AVERAGEIF(Clean_Data!$Q:$Q,A13,Clean_Data!$E:$E) | C13: =INDEX(Clean_Data!$E:$E,MATCH(A13,Clean_Data!$Q:$Q,0)) | D13: =LOOKUP(2,1/(Clean_Data!$Q:$Q=A13),Clean_Data!$E:$E) | E13: =D13/C13-1 | F13: =MAXIFS(Clean_Data!$E:$E,Clean_Data!$Q:$Q,A13) | G13: =MINIFS(Clean_Data!$E:$E,Clean_Data!$Q:$Q,A13) | H13: =AVERAGEIF(Clean_Data!$Q:$Q,A13,Clean_Data!$F:$F)
A14: 2026 | B14: =AVERAGEIF(Clean_Data!$Q:$Q,A14,Clean_Data!$E:$E) | C14: =INDEX(Clean_Data!$E:$E,MATCH(A14,Clean_Data!$Q:$Q,0)) | D14: =LOOKUP(2,1/(Clean_Data!$Q:$Q=A14),Clean_Data!$E:$E) | E14: =D14/C14-1 | F14: =MAXIFS(Clean_Data!$E:$E,Clean_Data!$Q:$Q,A14) | G14: =MINIFS(Clean_Data!$E:$E,Clean_Data!$Q:$Q,A14) | H14: =AVERAGEIF(Clean_Data!$Q:$Q,A14,Clean_Data!$F:$F)

Sheet Monthly_Analysis
A1: Month | B1: Average Close | C1: Average Volume | D1: Average Daily Return %
A2: 1 | B2: =AVERAGEIF(Clean_Data!$R:$R,A2,Clean_Data!$E:$E) | C2: =AVERAGEIF(Clean_Data!$R:$R,A2,Clean_Data!$F:$F) | D2: =AVERAGEIF(Clean_Data!$R:$R,A2,Clean_Data!$I:$I)
A3: 2 | B3: =AVERAGEIF(Clean_Data!$R:$R,A3,Clean_Data!$E:$E) | C3: =AVERAGEIF(Clean_Data!$R:$R,A3,Clean_Data!$F:$F) | D3: =AVERAGEIF(Clean_Data!$R:$R,A3,Clean_Data!$I:$I)
A4: 3 | B4: =AVERAGEIF(Clean_Data!$R:$R,A4,Clean_Data!$E:$E) | C4: =AVERAGEIF(Clean_Data!$R:$R,A4,Clean_Data!$F:$F) | D4: =AVERAGEIF(Clean_Data!$R:$R,A4,Clean_Data!$I:$I)
A5: 4 | B5: =AVERAGEIF(Clean_Data!$R:$R,A5,Clean_Data!$E:$E) | C5: =AVERAGEIF(Clean_Data!$R:$R,A5,Clean_Data!$F:$F) | D5: =AVERAGEIF(Clean_Data!$R:$R,A5,Clean_Data!$I:$I)
A6: 5 | B6: =AVERAGEIF(Clean_Data!$R:$R,A6,Clean_Data!$E:$E) | C6: =AVERAGEIF(Clean_Data!$R:$R,A6,Clean_Data!$F:$F) | D6: =AVERAGEIF(Clean_Data!$R:$R,A6,Clean_Data!$I:$I)
A7: 6 | B7: =AVERAGEIF(Clean_Data!$R:$R,A7,Clean_Data!$E:$E) | C7: =AVERAGEIF(Clean_Data!$R:$R,A7,Clean_Data!$F:$F) | D7: =AVERAGEIF(Clean_Data!$R:$R,A7,Clean_Data!$I:$I)
A8: 7 | B8: =AVERAGEIF(Clean_Data!$R:$R,A8,Clean_Data!$E:$E) | C8: =AVERAGEIF(Clean_Data!$R:$R,A8,Clean_Data!$F:$F) | D8: =AVERAGEIF(Clean_Data!$R:$R,A8,Clean_Data!$I:$I)
A9: 8 | B9: =AVERAGEIF(Clean_Data!$R:$R,A9,Clean_Data!$E:$E) | C9: =AVERAGEIF(Clean_Data!$R:$R,A9,Clean_Data!$F:$F) | D9: =AVERAGEIF(Clean_Data!$R:$R,A9,Clean_Data!$I:$I)
A10: 9 | B10: =AVERAGEIF(Clean_Data!$R:$R,A10,Clean_Data!$E:$E) | C10: =AVERAGEIF(Clean_Data!$R:$R,A10,Clean_Data!$F:$F) | D10: =AVERAGEIF(Clean_Data!$R:$R,A10,Clean_Data!$I:$I)
A11: 10 | B11: =AVERAGEIF(Clean_Data!$R:$R,A11,Clean_Data!$E:$E) | C11: =AVERAGEIF(Clean_Data!$R:$R,A11,Clean_Data!$F:$F) | D11: =AVERAGEIF(Clean_Data!$R:$R,A11,Clean_Data!$I:$I)
A12: 11 | B12: =AVERAGEIF(Clean_Data!$R:$R,A12,Clean_Data!$E:$E) | C12: =AVERAGEIF(Clean_Data!$R:$R,A12,Clean_Data!$F:$F) | D12: =AVERAGEIF(Clean_Data!$R:$R,A12,Clean_Data!$I:$I)
A13: 12 | B13: =AVERAGEIF(Clean_Data!$R:$R,A13,Clean_Data!$E:$E) | C13: =AVERAGEIF(Clean_Data!$R:$R,A13,Clean_Data!$F:$F) | D13: =AVERAGEIF(Clean_Data!$R:$R,A13,Clean_Data!$I:$I)
